Workbook
Name _Hlk32486461: Proposal!#REF!
Name GRAND: #REF!
Name OLE_LINK1: Proposal!#REF!
Name Print_Area_MI: #REF!
Name Print_Titles_MI: #REF!,#REF!
Name xx: '[1]AIA G702'!$73:$380,'[1]AIA G702'!$C$5:$DH$16389

Sheet RECAP
J1: Quote #: | K1: E26-XXX
J2: Date: | K2: =TODAY() -> 46238
J3: Estimator:
I4: =_xlfn.XLOOKUP(K3,A56:A57,B56:B57, "E-Mail") -> E-Mail
J5: Profit: | K5: =F53/G53 -> #DIV/0!
I6: Material $/lb: | K6: =(D28+D42)/(Structural!D15+Misc.!D14) -> #DIV/0!
A9: Customer Name: | G9: Project Location: | I9: (Physical Address)
A10: Project Name: | I10: (City, State)
A11: Tons: | B11: =(Structural!D15+Misc.!D14)/2000 -> 0 | C11: Man Hrs: | D11: =Labor!B13+Labor!B27 -> 0 | E11: Man Hrs/Ton: | G11: =D11/B11 -> #DIV/0! | H11: FOB or Erected:
A13: Shop Information:
A14: Structural Labor (hrs.): | D14: =Labor!B13 -> 0 | F14: Structural Labor Rate ($/hr.): | I14: 85
A15: Outsourced Labor (hrs.): | D15: =Outsourced!D14 -> 0 | F15: Outsourced Labor Rate ($/hr.): | I15: 65
A16: Misc Labor (hrs.): | D16: =Labor!B27 -> 0 | F16: Misc. Labor Rate ($/hr.): | I16: 100
A17: Paint Surface (sq. ft.): | F17: 300 | G17: Paint($/gal.): | I17: 38
A18: Galvanizing (lbs.): | D18: =Structural!C15+Misc.!C14 -> 0 | F18: Galvanizing ($/lb.): | I18: 0.45
A19: Galv Freight (del.): | F19: Galv Freight ($/del.): | I19: 1500
A20: Jobsite Freight (del.): | F20: Jobsite Freight ($/del.): | I20: 1000
A22: Pricing Analysis:
A23: Description: | D23: Cost: | E23: Profit Markup | G23: Sell Price: | H23: Cost Per Ton: | I23: % of Job: | J23: Lowest Vendor Quote:
E24: %: | F24: $:
A25: Detailing | E25: 0.1 | F25: =D25*E25 -> 0 | G25: =D25+F25 -> 0 | H25: =IFERROR((D25/$B$11),"") | I25: =IFERROR((G25/$G$53),"")
A26: Engineering | E26: 0.1 | F26: =D26*E26 -> 0 | G26: =D26+F26 -> 0 | H26: =IFERROR((D26/$B$11),"") | I26: =IFERROR((G26/$G$53),"")
A27: BIM | E27: 0.1 | F27: =D27*E27 -> 0 | G27: =D27+F27 -> 0 | H27: =IFERROR((D27/$B$11),"") | I27: =IFERROR((G27/$G$53),"")
A28: Structural Material | D28: =Structural!F15 -> 0 | E28: 0.1 | F28: =D28*E28 -> 0 | G28: =D28+F28 -> 0 | H28: =IFERROR((D28/$B$11),"") | I28: =IFERROR((G28/$G$53),"")
A29: Bolts/Fasteners | D29: =Structural!D25 -> 0 | E29: 0.1 | F29: =D29*E29 -> 0 | G29: =D29+F29 -> 0 | H29: =IFERROR((D29/$B$11),"") | I29: =IFERROR((G29/$G$53),"")
A30: Outsourced Fabrication | E30: 0.1 | F30: =D30*E30 -> 0 | G30: =D30+F30 -> 0 | H30: =IFERROR((D30/$B$11),"") | I30: =IFERROR((G30/$G$53),"")
A31: Structural Fabrication | D31: =Labor!D13-Labor!D5-Labor!D19 -> 0 | E31: 0.1 | F31: =D31*E31 -> 0 | G31: =D31+F31 -> 0 | H31: =IFERROR((D31/$B$11),"") | I31: =IFERROR((G31/$G$53),"")
A32: Galvanizing | D32: =(D18*I18)+(D19*I19) -> 0 | E32: 0.1 | F32: =D32*E32 -> 0 | G32: =D32+F32 -> 0 | H32: =IFERROR((D32/$B$11),"") | I32: =IFERROR((G32/$G$53),"")
A33: Steel Rolling | E33: 0.1 | F33: =D33*E33 -> 0 | G33: =D33+F33 -> 0 | H33: =IFERROR((D33/$B$11),"") | I33: =IFERROR((G33/$G$53),"")
A34: Joist & Deck | D34: ='J&D'!D8 -> 0 | E34: 0.1 | F34: =D34*E34 -> 0 | G34: =D34+F34 -> 0 | H34: =IFERROR((D34/$B$11),"") | I34: =IFERROR((G34/$G$53),"")
A35: Anchor Bolts | D35: =Structural!D35 -> 0 | E35: 0.1 | F35: =D35*E35 -> 0 | G35: =D35+F35 -> 0 | H35: =IFERROR((D35/$B$11),"") | I35: =IFERROR((G35/$G$53),"")
A36: Shop Priming | D36: =((D17/F17)*I17)+Labor!D5+Labor!D19 -> 0 | E36: 0.1 | F36: =D36*E36 -> 0 | G36: =D36+F36 -> 0 | H36: =IFERROR((D36/$B$11),"") | I36: =IFERROR((G36/$G$53),"")
A37: Grating | D37: =Misc.!F6 -> 0 | E37: 0.1 | F37: =D37*E37 -> 0 | G37: =D37+F37 -> 0 | H37: =IFERROR((D37/$B$11),"") | I37: =IFERROR((G37/$G$53),"")
A38: Outsourced Paint | E38: 0.1 | F38: =D38*E38 -> 0 | G38: =D38+F38 -> 0 | H38: =IFERROR((D38/$B$11),"") | I38: =IFERROR((G38/$G$53),"")
A39: Outsourced Shot Blasting | E39: 0.1 | F39: =D39*E39 -> 0 | G39: =D39+F39 -> 0 | H39: =IFERROR((D39/$B$11),"") | I39: =IFERROR((G39/$G$53),"")
A40: Jobsite Freight (Material Delivery) | D40: =D20*I20 -> 0 | E40: 0.1 | F40: =D40*E40 -> 0 | G40: =D40+F40 -> 0 | H40: =IFERROR((D40/$B$11),"") | I40: =IFERROR((G40/$G$53),"")
A41: Misc. Fabrication | D41: =Labor!D27 -> 0 | E41: 0.1 | F41: =D41*E41 -> 0 | G41: =D41+F41 -> 0 | H41: =IFERROR((D41/$B$11),"") | I41: =IFERROR((G41/$G$53),"")
A42: Misc. Material | D42: =Misc.!F14-Misc.!F6 -> 0 | E42: 0.1 | F42: =D42*E42 -> 0 | G42: =D42+F42 -> 0 | H42: =IFERROR((D42/$B$11),"") | I42: =IFERROR((G42/$G$53),"")
A43: Steel Erection | E43: 0.1 | F43: =D43*E43 -> 0 | G43: =D43+F43 -> 0 | H43: =IFERROR((D43/$B$11),"") | I43: =IFERROR((G43/$G$53),"")
A44: Outsourced Misc. Material & Erection | D44: =Outsourced!B14+Outsourced!E14 -> 0 | E44: 0.1 | F44: =D44*E44 -> 0 | G44: =D44+F44 -> 0 | H44: =IFERROR((D44/$B$11),"") | I44: =IFERROR((G44/$G$53),"")
...

Sheet Structural
A1: Structural Material:
A2: Description: | B2: Weight | E2: $/LB: | F2: Cost ($):
B3: Painted: | C3: Galv. | D3: Total:
A4: Structural Material Package | D4: =SUM(B4:C4) -> 0 | F4: =D4*E4 -> 0
A5: Plate Summary | D5: =SUM(B5:C5) -> 0 | F5: =D5*E5 -> 0
A6: Lintels | D6: =SUM(B6:C6) -> 0 | F6: =D6*E6 -> 0
D7: =SUM(B7:C7) -> 0 | F7: =D7*E7 -> 0
D8: =SUM(B8:C8) -> 0 | F8: =D8*E8 -> 0
D9: =SUM(B9:C9) -> 0 | F9: =D9*E9 -> 0
D10: =SUM(B10:C10) -> 0 | F10: =D10*E10 -> 0
D11: =SUM(B11:C11) -> 0 | F11: =D11*E11 -> 0
D12: =SUM(B12:C12) -> 0 | F12: =D12*E12 -> 0
D13: =SUM(B13:C13) -> 0 | F13: =D13*E13 -> 0
A14: % Escalation Allowance | B14: N/A | C14: N/A | D14: 0 | F14: {=SUM(F4:F13*D14)} -> 0
A15: Totals: | B15: =SUM(B4:B14) -> 0 | C15: =SUM(C4:C14) -> 0 | D15: =SUM(D4:D13) -> 0 | F15: =SUM(F4:F14) -> 0
A17: Bolts/Fasteners:
A18: Description: | B18: Quantity: | C18: $/Unit: | D18: Cost ($):
D19: =B19*C19 -> 0
D20: =B20*C20 -> 0
D21: =B21*C21 -> 0
D22: =B22*C22 -> 0
D23: =B23*C23 -> 0
D24: =B24*C24 -> 0
A25: Total: | D25: =SUM(D19:D24) -> 0
A27: Anchor Bolts:
A28: Description: | B28: Quantity: | C28: $/Unit: | D28: Cost ($):
D29: =B29*C29 -> 0
D30: =B30*C30 -> 0
D31: =B31*C31 -> 0
D32: =B32*C32 -> 0
D33: =B33*C33 -> 0
D34: =B34*C34 -> 0
A35: Total: | D35: =SUM(D29:D34) -> 0

Sheet J&D
A1: Joist:
A2: Description: | B2: Pieces: | C2: Tonnage: | D2: Cost ($):
A8: Totals: | B8: =SUM(B3:B7) -> 0 | C8: =SUM(C3:C7) -> 0 | D8: 0
D9: Enter total amount above from J&D's proposal.
A10: Deck:
A11: Description: | B11: Squares:
A17: Totals: | B17: =SUM(B12:B16) -> 0

Sheet Misc.
A1: Misc. Materials:
A2: Description: | B2: Weight | E2: $/LB: | F2: Cost ($):
B3: Painted: | C3: Galv. | D3: Total:
A4: Steel | D4: =SUM(B4:C4) -> 0 | F4: =D4*E4 -> 0
A5: Plate | D5: =SUM(B5:C5) -> 0 | F5: =D5*E5 -> 0
A6: Grating | D6: =SUM(B6:C6) -> 0 | F6: =D6*E6 -> 0
A7: Bollards | D7: =SUM(B7:C7) -> 0 | F7: =D7*E7 -> 0
D8: =SUM(B8:C8) -> 0 | F8: =D8*E8 -> 0
D9: =SUM(B9:C9) -> 0 | F9: =D9*E9 -> 0
D10: =SUM(B10:C10) -> 0 | F10: =D10*E10 -> 0
D11: =SUM(B11:C11) -> 0 | F11: =D11*E11 -> 0
D12: =SUM(B12:C12) -> 0 | F12: =D12*E12 -> 0
D13: =SUM(B13:C13) -> 0 | F13: =D13*E13 -> 0
A14: Totals: | B14: =SUM(B4:B13) -> 0 | C14: =SUM(C4:C13) -> 0 | D14: =SUM(D4:D13) -> 0 | F14: =SUM(F4:F13) -> 0

Sheet Outsourced
A1: Outsourced Materials, Fabrication & Erection:
A2: Scope Description: | B2: Material ($): | C2: Fabrication: | E2: Erection ($): | F2: Comment:
C3: ($): | D3: Hours:
A14: Totals: | B14: =SUM(B4:B13) -> 0 | C14: =SUM(C4:C13) -> 0 | D14: =SUM(D4:D13) -> 0 | E14: =SUM(E4:E13) -> 0

Sheet Labor
A1: Structural Fabrication:
A2: Description: | B2: Hours: | C2: $/Hour: | D2: Cost ($):
A3: Structural Fabrication | C3: =RECAP!$I$14 -> 85 | D3: =B3*C3 -> 0
A4: Processing Steel | C4: =RECAP!$I$14 -> 85 | D4: =B4*C4 -> 0
A5: Shop Priming | C5: =RECAP!$I$14 -> 85 | D5: =B5*C5 -> 0
A6: Load/Unload Material | C6: =RECAP!$I$14 -> 85 | D6: =B6*C6 -> 0
C7: =RECAP!$I$14 -> 85 | D7: =B7*C7 -> 0
C8: =RECAP!$I$14 -> 85 | D8: =B8*C8 -> 0
C9: =RECAP!$I$14 -> 85 | D9: =B9*C9 -> 0
C10: =RECAP!$I$14 -> 85 | D10: =B10*C10 -> 0
C11: =RECAP!$I$14 -> 85 | D11: =B11*C11 -> 0
C12: =RECAP!$I$14 -> 85 | D12: =B12*C12 -> 0
A13: Totals: | B13: =SUM(B3:B12) -> 0 | D13: =SUM(D3:D12) -> 0
A15: Misc. Fabrication:
A16: Description: | B16: Hours: | C16: $/Hour: | D16: Cost ($):
A17: Misc. Fabrication | C17: =RECAP!$I$16 -> 100 | D17: =B17*C17 -> 0
A18: Processing Steel | C18: =RECAP!$I$14 -> 85 | D18: =B18*C18 -> 0
A19: Shop Priming | C19: =RECAP!$I$14 -> 85 | D19: =B19*C19 -> 0
A20: Load/Unload Material | C20: =RECAP!$I$14 -> 85 | D20: =B20*C20 -> 0
C21: =RECAP!$I$16 -> 100 | D21: =B21*C21 -> 0
C22: =RECAP!$I$16 -> 100 | D22: =B22*C22 -> 0
C23: =RECAP!$I$16 -> 100 | D23: =B23*C23 -> 0
C24: =RECAP!$I$16 -> 100 | D24: =B24*C24 -> 0
C25: =RECAP!$I$16 -> 100 | D25: =B25*C25 -> 0
C26: =RECAP!$I$16 -> 100 | D26: =B26*C26 -> 0
A27: Totals: | B27: =SUM(B17:B26) -> 0 | D27: =SUM(D17:D26) -> 0

Sheet Allowance
A1: ALLOWANCE:
A3: Description: | B3: Cost ($): | C3: Comment:
A10: Totals: | B10: =SUM(B4:B9) -> 0

Sheet Addtn'l (AKP)
A1: Additional Costs:
A2: Insurance: | B2: (Y or N): | C2: Rate: | D2: Cost: | E2: Comment:
A3: Builder's Risk Buy Down: | C3: 3000 | D3: =IF(B3="Y",C3,0) -> 0 | E3: Per year; up to $2M; job scope structural steel, deck, joist, beams, handrails, ladders; Up to $50K; policy deductible $2,500; Over $2M obtain cost from USI Insurance
A4: General Liability: | D4: =IF(B4="Y",C4,0) -> 0 | E4: Additional coverage required
A5: Umbrella: | D5: =IF(B5="Y",C5,0) -> 0 | E5: Additional coverage required
A6: Professional Liability: | D6: =IF(B6="Y",C6,0) -> 0 | E6: Additional coverage required
D7: =IF(B7="Y",C7,0) -> 0
A8: Total: | D8: =SUM(D3:D7) -> 0
A10: Performance / Payment Bond: | B10: (Y or N): | C10: Rate*: | D10: Recap Subtotal: | E10: Cost: | F10: Comment:
D11: =IF(B11="Y",(RECAP!G50+RECAP!G52+'Addtn''l (AKP)'!E36),0) -> 0 | F11: Includes Recap Subtotal, Textura/Procore Pay with OH&P and Sales Tax
A12: $0.01 - $500,000: | C12: 0.0081 | D12: =MIN($D$11,500000) -> 0 | E12: =IFERROR((D12*C12),"") -> 0
A13: $500,001 - $2,500,000: | C13: 0.00567 | D13: =MAX(MIN($D$11-D12,2000000),0) -> 0 | E13: =IFERROR((D13*C13),"") -> 0
A14: $2,500,001 - $5,000,000: | C14: 0.00486 | D14: =MAX(MIN($D$11-SUM($D$12:D13),2500000),0) -> 0 | E14: =IFERROR((D14*C14),"") -> 0
A15: $5,000,00+: | C15: 0.00432 | D15: =MAX($D$11-SUM($D$12:D14),0) -> 0 | E15: =IFERROR((D15*C15),"") -> 0
A16: $7,500,000+ | E16: =IFERROR((D16*#REF!),"")
A17: Total: | E17: =SUM(E12:E16) -> 0
A19: Procore Pay/Textura: | B19: (Y or N): | C19: Fee: | D19: Sales Tax: | E19: Total: | F19: Comment:
A20: Project Pay: | C20: =IF($B$20="Y",((SUM(RECAP!$G$50+RECAP!$G$51)*0.2%)),0) -> 0 | D20: =C20*6.75% -> 0 | E20: =IF(B20="Y",MIN(C20+D20,"$4,270.00"),0) -> 0
A21: Textura: | C21: =IF($B$21="Y",((SUM(RECAP!$G$50+RECAP!$G$51)*0.2%)),0) -> 0 | D21: =C21*6.75% -> 0 | E21: =IF(B21="Y",MIN(C21+D21,"$5,337.50"),0) -> 0
A22: Total: | E22: =E20+E21 -> 0
A24: LEED Level / Government Job: | B24: N/A | C24: Hours: | D24: Rate: | E24: Cost: | F24: Comment:
A25: Certified: | C25: 30 | D25: 50 | E25: =IF($B$24="Certified", C25*D25, 0) -> 0
A26: Silver: | C26: 50 | D26: 50 | E26: =IF($B$24="Silver", C26*D26, 0) -> 0
A27: Gold: | C27: 80 | D27: 50 | E27: =IF($B$24="Gold", C27*D27, 0) -> 0
A28: Platinum: | C28: 120 | D28: 50 | E28: =IF($B$24="Platinum", C28*D28, 0) -> 0
A29: Government Job: | C29: 140 | D29: 50 | E29: =IF($B$24="Government", C29*D29, 0) -> 0
A30: $7,500,000+
A31: Total: | E31: =SUM(E25:E30) -> 0
A33: Sales Tax: | D33: Recap Total: | E33: Total Cost: | F33: Comment:
A34: Tax County/Rate: | B34: Tax Exempt | C34: =VLOOKUP($B$34, $C$39:$D$45, 2, FALSE) -> 0 | D34: =RECAP!G50-RECAP!G43-Outsourced!E14-(Outsourced!E14*RECAP!E44) -> 0 | E34: =IFERROR((D34*C34),"") -> 0 | F34: Sales tax calculated on all except Erection, J&D cost, Procore Pay/Textura fees & Bond cost (if applicable)
A35: Project County/Rate: | D35: =RECAP!D34 -> 0 | E35: =IFERROR((D35*C35),"") -> 0 | F35: Joist & Deck cost (mark-up included above)
A36: Total: | E36: =SUM(E34:E35) -> 0
A38: *Rates effective 03/26/26 | B38: Tax Area: | D38: Tax Rate: | E38: Change Date: | F38: Sales tax rates are subject to change. Ask Anne or Alexia to verify the current rate before quoting to a customer.
C39: Tax Exempt | D39: 0
C40: Hancock | D40: 0.0675
C41: Indiana | D41: 0.07 | E41: 2008
C42: Kentucky | D42: 0.06
C43: Michigan | D43: 0.06 | E43: 1994
C44: UT: American Fork | D44: 0.0745 | E44: Jan. '26
C45: UT: Heber City | D45: 0.0835 | E45: Jan. '26

Sheet Proposal
O2: 813 E Bigelow Avenue
O3: Findlay, OH 45840
O4: Phone: 419-424-1217
A7: Date: | B7: =RECAP!K2 -> 46238 | I7: Proposal Expires: | L7: =B7+6 -> 46244 | N7: Quote #: | Q7: =RECAP!K1 -> E26-XXX
A9: Project: | C9: =RECAP!C10 -> 0 | N9: Customer (Buyer): | R9: =RECAP!C9 -> 0
C10: =RECAP!I10 -> (City, State) | N10: Attention:
A12: Specification Sections:
A13: Drawings Used:
A14: Supplied Cut Sheet:
A19: Addendums:
A21: Includes:
A22: - XX Columns
A23: -
A24: -
A25: -
A26: -
A27: -
A28: -
... A59: + Must Ship Complete by Date:
A61: Alternates: | M61: Allowances:
A63: F.O.B. Jobsite (Supply Only - Not Erected) | V63: F.O.B. Jobsite (Supply Only - Not Erected)
A64: Total Price (Excluding Sales Tax): | R64: =RECAP!G53 -> 0 | V64: Fabricated, Delivered, and Installed
A65: Sales Tax: | R65: ='Addtn''l (AKP)'!E36 -> 0
A66: Total Price (Including Sales Tax): | R66: =SUM(R64:R65) -> 0
A67: Unless a sales tax exemption certificate is received, the current sales tax rate on the date of the invoice will be added.
A69: Structural Steel: | G69: =RECAP!B11 -> 0 | H69: Tons | R69: Sincerely,
A70: Steel Joist: | G70: ='J&D'!B8 -> 0 | H70: Pc's | I70: ='J&D'!C8 -> 0 | J70: Tons | R70: =RECAP!K3 -> 0
A71: Metal Deck: | G71: ='J&D'!B17 -> 0 | H71: Squares | O71: E-Mail: | R71: =RECAP!I4 -> E-Mail
A72: Escalation is Based on Today's Prices. Quote is valid for seven (7) days after which time pricing it is subject to review.
A73: SEE BELOW TERMS AND CONDITIONS WHICH ARE INCORPORATED INTO THIS PROPOSAL AND CONTRACT WITH CUSTOMER (BUYER).
A75: STANDARD TERMS & CONDITIONS OF SALE
A76: ARTICLE 1 – PROPOSAL TERMS AND CONTRACT DOCUMENTS:
A77: 1.1 | B77: These Standard Terms & Conditions of Sale are part of Hancock Structural Steel, LLC’s (“Seller”) Proposal (the “Proposal”). “Buyer” or “Buyer” means the Buyer listed in the Proposal.
A78: 1.2 | B78: PROPOSAL TERMS. This offer is expressly limited to these terms, and any attempt to add to such terms shall be deemed a rejection and a counteroffer, which may result in a withdrawal of this Proposal or a modification in price.
A79: 1.2.1 | C79: If this Proposal is accepted, and the Buyer’s order is issued for that purpose, it is expressly agreed that the terms and conditions of this Proposal shall prevail insofar as the same may in any way conflict with the terms and conditions set forth in the Buyer’s order form, and the issuance of such order form by the Buyer shall be deemed to be the Buyer’s assent to the foregoing.
A80: 1.2.2 | C80: If, as a result of this provision, Seller is asked or required to enter into a separate written agreement beyond the terms of this Proposal, then, in that event, Seller reserves the right to review the general terms and conditions of the proposed agreement and the right to reject any and all terms and conditions of said agreement which are in conflict with or vary the terms of this Proposal.
A81: 1.2.3 | C81: Time Limit of Proposal. Unless modified by the Proposal or given a directive to proceed resulting in a Contract as set forth in Article 1.3, the Proposal shall be valid for seven (7) days from the date provided thereon, and thereafter shall automatically terminate unless extended in writing by Seller. The Proposal is made with reference to steel prices in effect on the date of the Proposal. This Proposal may be changed or revoked at any time by Seller prior to acceptance.
A82: 1.3 | B82: CONTRACT. In the event, prior to the execution of a mutually agreeable contract, that Seller is directed to purchase material, begin the shop drawing process, or otherwise commence any of the work contemplated by this Proposal, this Proposal shall be deemed accepted, and becomes a binding agreement. Seller reserves the right to refuse or negotiate terms of any other proposed agreement presented by the Buyer as a substitution to these STANDARD TERMS & CONDITIONS OF SALE.
A83: 1.3.1 | C83: No terms and conditions contained in the agreement between Owner and Buyer, if applicable, shall be binding on Seller unless a copy of such terms and conditions has been furnished to Seller and accepted in writing signed by the Seller.
A84: 1.3.2 | C84: The parties expressly agree that this Proposal embodies their entire Contract; any subsequent cancellations or modifications must be agreed upon in writing.
...

Sheet COST CODES
G1: Quote # | H1: =RECAP!K1 -> E26-XXX
G2: Date: | H2: =TODAY() -> 46238
G3: Estimator: | H3: =RECAP!K3 -> 0
G4: Job #:
A5: =RECAP!C10 -> 0
A6: =RECAP!I10 -> (City, State)
A7: Cost Code: | C7: Description: | G7: Cost: | H7: Vendor:
A8: 01-970 | C8: Procore Pay/Textura Fee Including Sales Tax | G8: =RECAP!D52 -> 0
A9: 05-010 | C9: Detailing | G9: =RECAP!D25 -> 0 | H9: =RECAP!J25 -> 0
A10: 05-011 | C10: Engineering | G10: =RECAP!D26 -> 0 | H10: =RECAP!J26 -> 0
A11: 05-012 | C11: BIM | G11: =RECAP!D27 -> 0 | H11: =RECAP!J27 -> 0
A12: 05-105 | C12: Structural Material | G12: =RECAP!D28 -> 0
A13: 05-106 | C13: Bolts/Fasteners | G13: =RECAP!D29 -> 0
A14: 05-110 | C14: =RECAP!D15 -> 0 | D14: Hrs | E14: Outsourced Fabrication | G14: =RECAP!D30 -> 0 | H14: =RECAP!J30 -> 0
A15: 05-121 | C15: =Labor!B13-SUM(Labor!B4:B6) -> 0 | D15: Hrs | E15: Structural Fabrication | G15: =RECAP!D31 -> 0
A16: 05-122 | C16: Galvanizing | G16: =RECAP!D32 -> 0
A17: 05-123 | C17: =Labor!B4+Labor!B18 -> 0 | D17: Hrs | E17: Processing Steel | G17: =Labor!D4+Labor!D18 -> 0
A18: 05-124 | C18: Steel Rolling | G18: =RECAP!D33 -> 0
A19: 05-210 | C19: Joist and Deck | G19: =RECAP!D34 -> 0 | H19: =RECAP!J34 -> 0
A20: 05-301 | C20: Anchor Bolts | G20: =RECAP!D35 -> 0
A21: 05-302 | C21: =Labor!B5+Labor!B19 -> 0 | D21: Hrs | E21: Shop Priming (Labor & Material) | G21: =RECAP!D36 -> 0
A22: 05-303 | C22: Grating | G22: =RECAP!D37 -> 0
A23: 05-305 | C23: Outsourced Paint | G23: =RECAP!D38 -> 0 | H23: =RECAP!J38 -> 0
A24: 05-306 | C24: Outsourced Shot Blasting | G24: =RECAP!D39 -> 0 | H24: =RECAP!J39 -> 0
A25: 05-400 | C25: =Labor!B6+Labor!B20 -> 0 | D25: Hrs | E25: Load/Unload Material | G25: =Labor!D6+Labor!D20 -> 0
A26: 05-401 | C26: Jobsite Freight (Material Delivery) | G26: =RECAP!D40 -> 0
A27: 05-500 | C27: =Labor!B27-SUM(Labor!B18:B20) -> 0 | D27: Hrs | E27: Misc. Fabrication | G27: =RECAP!D41-Labor!D18-Labor!D19-Labor!D20 -> 0
A28: 05-510 | C28: Misc. Material | G28: =RECAP!D42 -> 0
A29: 05-600 | C29: Steel Erection | G29: =RECAP!D43 -> 0 | H29: =RECAP!J43 -> 0
A30: 05-601 | C30: Misc. Material & Erection | G30: =RECAP!D44 -> 0 | H30: =RECAP!J44 -> 0
A31: 05-602 | C31: Subcontractor Other | G31: =RECAP!D45 -> 0 | H31: =RECAP!J45 -> 0
A32: 05-999 | C32: Allowance(s) | G32: =RECAP!D46 -> 0
C33: HSS Contingency | G33: =RECAP!D47 -> 0
A34: 17-994 | C34: Insurance | G34: =RECAP!D48 -> 0
A35: 17-996 | C35: Performance/Payment Bond | G35: =RECAP!D51 -> 0
A36: Subtotal: | G36: =SUM(G8:G35) -> 0
A37: Total Profit for Project: | G37: =RECAP!G53-'COST CODES'!G36 -> 0
A38: Grand Total: | G38: =SUM(G36:G37) -> 0
E40: Difference from Proposal Amount: | G40: =RECAP!G53-'COST CODES'!G38 -> 0

Sheet Estimator Notes
A1: Project Name: | B1: Estimate Number: | C1: Bid Date: | D1: Drawing Date: | E1: Notes:
A2: =RECAP!C10 -> 0 | B2: =RECAP!K1 -> E26-XXX
A8: Addendum #: | B8: Addendum Date: | C8: Addendum Notes:
A16: Date: | B16: Notes:

Sheet Contract Review Record
B2: Contract Review Record
B3: Job Name: | C3: =RECAP!C10 -> 0 | L3: Job #: | M3: 26-
B4: Estimator: | C4: =RECAP!K3 -> 0 | J4: Shop Hrs. | K4: =RECAP!D11 -> 0 | L4: Estimate # | M4: E26-
B5: ITEMS & COMMENTS | N5: Check Box
N6: YES | O6: NO
B7: Specifications & plans received & recorded
B8: All Addendums received and recorded
B9: All plans, specifications, addendums (including post-bid) sent to erector, detailer, engineer, joist & deck suppliers, and any other vendors receiving a subcontract or purchase order? | AQ9: Erected
B10: All vendor quotes saved in estimate folder | AQ10: FOB
B11: Estimator Notes Attached
B12: Scope of Work Attached
B13: List of all sub quotes: | G13: Company: | L13: Type:
B17: Special/ Unusual Materials required list below:
B20: Engineering Required
B21: =[2]RECAP!F30 -> -
B22: Detailing | I22: Company Name
B24: Joist & Deck required
B25: =[2]RECAP!F31 -> -
B26: Special Shipping Instructions
B28: TC Bolt Required?
B30: Fire Proofing
B31: =[2]MATERIALS!B5 -> (any Fire proofing type Y or N)
B32: Surface Preparation / Primer / Finish Paint Instruction of surface rep
B34: Galvanizing | I34: Tons
B36: Are there beams with Camber
B38: Erected or FOB | H38: Who's the Erector?
B40: Lintels
B42: Embeds
B44: Sequencing
B46: Turnover Meeting Required Attendees:
B47: Joshua Waller
B48: Paul Hostetter
B49: Bill Holtfreter
B50: Andy Boyce
B51: Rick Lonsway
B52: Nikki Perkins
B53: Justin Chagnon
